<?xml version="1.0" encoding="utf-8" standalone="yes" ?>
<rss version="2.0" xmlns:atom="http://www.w3.org/2005/Atom">
  <channel>
    <title>Django on Mildly Skilled</title>
    <link>/tags/django/</link>
    <description>Recent content in Django on Mildly Skilled</description>
    <generator>Hugo -- gohugo.io</generator>
    <language>en-gb</language>
    <lastBuildDate>Thu, 23 Oct 2014 14:15:42 +0100</lastBuildDate>
    
	<atom:link href="/tags/django/index.xml" rel="self" type="application/rss+xml" />
    
    
    <item>
      <title>Django Bug?</title>
      <link>/posts/django-bug/</link>
      <pubDate>Thu, 23 Oct 2014 14:15:42 +0100</pubDate>
      
      <guid>/posts/django-bug/</guid>
      <description>After spending hours trying to debug why my settings file was not being found I stumbled across this
I&amp;rsquo;ve found the answer to my question.
If you&amp;rsquo;ve got an error in your settings, manage.py will swallow the exception and report as if the command does not exist. This lead me down the path of incorrectly assuming my python path or venv environment was messed up. If you want to diagnose this issue, run&amp;hellip;</description>
    </item>
    
  </channel>
</rss>